Workbook

Sheet Purchase 2
A5: Louise | B5: Old | E5: New | H5: Total Purchase | I5: Total Profit | J5: Total Margin | L5: Manisha | M5: Old | P5: New | S5: Total Purchase | T5: Total Profit | U5: Total Margin
B6: Purchase | C6: Profit | D6: Margin | E6: Purchase | F6: Profit | G6: Margin | M6: Purchase | N6: Profit | O6: Margin | P6: Purchase | Q6: Profit | R6: Margin
A7: Jan | B7: 2201358 | C7: 1316676.5 | D7: 0.59812009 | E7: 16373.57 | F7: 474.97 | G7: 0.029008335 | H7: 2217731.6 | I7: 1317151.4 | J7: 0.59391832 | L7: Jan | M7: 967037.27 | N7: 102472.31 | O7: 0.10596521 | P7: 0 | Q7: 0 | R7: 0 | S7: 967037.27 | T7: 102472.31 | U7: 0.10596521
A8: Feb | B8: 2778078.7 | C8: 1473980.8 | D8: 0.53057562 | E8: 12781.88 | F8: 657.08 | G8: 0.051407148 | H8: 2790860.6 | I8: 1474637.9 | J8: 0.52838107 | L8: Feb | M8: 1099339.8 | N8: 185090 | O8: 0.16836469 | P8: 0 | Q8: 0 | R8: 0 | S8: 1099339.8 | T8: 185090 | U8: 0.16836469
A9: Mar | B9: 2636116.2 | C9: 1532995.3 | D9: 0.58153554 | E9: 30777.89 | F9: 4284.87 | G9: 0.1392191 | H9: 2666894.1 | I9: 1537280.1 | J9: 0.57643089 | L9: Mar | M9: 952578.01 | N9: 98425.613 | O9: 0.10332551 | P9: 0 | Q9: 0 | R9: 0 | S9: 952578.01 | T9: 98425.613 | U9: 0.10332551
A10: Apr | B10: 2112416.4 | C10: 1645020.2 | D10: 0.77873863 | E10: 38613.39 | F10: 16665.54 | G10: 0.43160002 | H10: 2151029.8 | I10: 1661685.8 | J10: 0.7725071 | L10: Apr | M10: 1216554.2 | N10: 131446.89 | O10: 0.10804853 | P10: 0 | Q10: 0 | R10: 0 | S10: 1216554.2 | T10: 131446.89 | U10: 0.10804853
A11: May | B11: 2695700.1 | C11: 1605401.8 | D11: 0.59554169 | E11: 163481.95 | F11: 31032.18 | G11: 0.18982022 | H11: 2859182.1 | I11: 1636434 | J11: 0.5723434 | L11: May | M11: 886917.18 | N11: 96862.18 | O11: 0.1092122 | P11: 45372 | Q11: 0 | R11: 0 | S11: 932289.18 | T11: 96862.18 | U11: 0.10389714
A12: Jun | B12: 2428765.8 | C12: 1129707.3 | D12: 0.46513638 | E12: 120395.29 | F12: 48524.65 | G12: 0.40304442 | H12: 2549161.1 | I12: 1178232 | J12: 0.46220381 | L12: Jun | M12: 1180769.1 | N12: 132576.29 | O12: 0.1122796 | P12: 0 | Q12: 0 | R12: 0 | S12: 1180769.1 | T12: 132576.29 | U12: 0.1122796
A13: Jul | B13: 2374302 | C13: 1350771.3 | D13: 0.568913 | E13: 502980.06 | F13: 411442.99 | G13: 0.81801054 | H13: 2877282.1 | I13: 1762214.3 | J13: 0.61245795 | L13: Jul | M13: 1083818.2 | N13: 112471.54 | O13: 0.10377344 | P13: 55775.12 | Q13: 6246.96 | R13: 0.11200263 | S13: 1139593.3 | T13: 118718.5 | U13: 0.1041762
A14: Aug | B14: 1960116.3 | C14: 1055441.8 | D14: 0.53845879 | E14: 462199.98 | F14: 405804.99 | G14: 0.87798574 | H14: 2422316.3 | I14: 1461246.8 | J14: 0.60324362 | L14: Aug | M14: 420238.97 | N14: 34938.3 | O14: 0.083139124 | P14: 986.01 | Q14: 0 | R14: 0 | S14: 421224.98 | T14: 34938.3 | U14: 0.082944511
A15: Grand Total | B15: 19186854 | C15: 11109995 | D15: 0.57904205 | E15: 1347604 | F15: 918887.27 | G15: 0.68186742 | H15: 20534458 | I15: 12028882 | J15: 0.58579012 | L15: Grand Total | M15: 7807252.8 | N15: 894283.12 | O15: 0.11454517 | P15: 102133.13 | Q15: 6246.96 | R15: 0.061164874 | S15: 7909385.9 | T15: 900530.08 | U15: 0.11385588
A17: Luca | B17: Old | E17: New | H17: Total Purchase | I17: Total Profit | J17: Total Margin | L17: Raffaella | M17: Old | P17: New | S17: Total Purchase | T17: Total Profit | U17: Total Margin
B18: Purchase | C18: Profit | D18: Margin | E18: Purchase | F18: Profit | G18: Margin | M18: Purchase | N18: Profit | O18: Margin | P18: Purchase | Q18: Profit | R18: Margin
A19: Jan | B19: 2792765.3 | C19: 382110.29 | D19: 0.13682148 | E19: 0 | F19: 0 | G19: 0 | H19: 2792765.3 | I19: 382110.29 | J19: 0.13682148 | L19: Jan | M19: 829570.02 | N19: 131800.38 | O19: 0.15887794 | P19: 9801.46 | Q19: 218.15 | R19: 0.022256888 | S19: 839371.48 | T19: 132018.53 | U19: 0.1572826
A20: Feb | B20: 2852746.8 | C20: 1847570.1 | D20: 0.64764604 | E20: 0 | F20: 0 | G20: 0 | H20: 2852746.8 | I20: 1847570.1 | J20: 0.64764604 | L20: Feb | M20: 1566070 | N20: 219347.4 | O20: 0.14006232 | P20: 8877.4 | Q20: 211.4 | R20: 0.023813279 | S20: 1574947.4 | T20: 219558.8 | U20: 0.13940706
A21: Mar | B21: 1893395.3 | C21: 737755.31 | D21: 0.38964673 | E21: 0 | F21: 0 | G21: 0 | H21: 1893395.3 | I21: 737755.31 | J21: 0.38964673 | L21: Mar | M21: 1271757.7 | N21: 186549.39 | O21: 0.14668627 | P21: 13170 | Q21: 340.4 | R21: 0.025846621 | S21: 1284927.7 | T21: 186889.79 | U21: 0.14544771
A22: Apr | B22: 2282257.4 | C22: 650898.67 | D22: 0.2851995 | E22: 1295.52 | F22: 0 | G22: 0 | H22: 2283552.9 | I22: 650898.67 | J22: 0.2850377 | L22: Apr | M22: 1478195.7 | N22: 275856.72 | O22: 0.18661719 | P22: 9643.2 | Q22: 1687.2 | R22: 0.17496267 | S22: 1487838.9 | T22: 277543.92 | U22: 0.18654165
A23: May | B23: 2678409.1 | C23: 674867.04 | D23: 0.25196563 | E23: 2932.52 | F23: 74.4 | G23: 0.025370671 | H23: 2681341.6 | I23: 674941.44 | J23: 0.25171781 | L23: May | M23: 1158977.8 | N23: 182799.24 | O23: 0.15772454 | P23: 90850.25 | Q23: 16113.66 | R23: 0.17736506 | S23: 1249828.1 | T23: 198912.9 | U23: 0.15915221
A24: Jun | B24: 2154404.3 | C24: 577277.63 | D24: 0.26795232 | E24: 38388.75 | F24: 7555.1 | G24: 0.19680505 | H24: 2192793.1 | I24: 584832.73 | J24: 0.26670676 | L24: Jun | M24: 1012399.3 | N24: 144398.61 | O24: 0.1426301 | P24: 49882 | Q24: 9275 | R24: 0.18593882 | S24: 1062281.3 | T24: 153673.61 | U24: 0.14466377
A25: Jul | B25: 3186268.8 | C25: 635277.72 | D25: 0.19937982 | E25: 45853.94 | F25: 22943.75 | G25: 0.50036594 | H25: 3232122.8 | I25: 658221.47 | J25: 0.2036499 | L25: Jul | M25: 1126515.5 | N25: 178770.31 | O25: 0.15869317 | P25: 70940.36 | Q25: 6287.07 | R25: 0.088624726 | S25: 1197455.8 | T25: 185057.38 | U25: 0.15454213
A26: Aug | B26: 1083001.5 | C26: 265513.77 | D26: 0.24516472 | E26: 43499.3 | F26: 9438.12 | G26: 0.21697177 | H26: 1126500.8 | I26: 274951.89 | J26: 0.24407606 | L26: Aug | M26: 358512.83 | N26: 54463.53 | O26: 0.15191515 | P26: 117255.76 | Q26: 10152.42 | R26: 0.08658355 | S26: 475768.59 | T26: 64615.95 | U26: 0.13581382
A27: Grand Total | B27: 18923249 | C27: 5771270.6 | D27: 0.30498308 | E27: 131970.03 | F27: 40011.37 | G27: 0.30318528 | H27: 19055219 | I27: 5811281.9 | J27: 0.30497062 | L27: Grand Total | M27: 8801998.8 | N27: 1373985.6 | O27: 0.15609927 | P27: 370420.43 | Q27: 44285.3 | R27: 0.11955415 | S27: 9172419.2 | T27: 1418270.9 | U27: 0.15462343

Sheet Buyer
A1: Countries | B1: Buyers | C1: Jan Purchases | D1: Jan Exp Profit | E1: Jan Exp Margin | F1: Feb Exp Purchases | G1: Feb Exp Profit | H1: Feb Exp Margin | I1: March Purchases | J1: April Purchases | K1: May Purchases | L1: June Purchases | M1: July Purchases | Q1: March Profit | R1: April Profit | S1: May Profit | T1: June Profit | U1: July Profit | Y1: March Margin | Z1: April Margin | AA1: May Margin | AB1: June Margin | AC1: July Margin | AE1: Total Purchase | AF1: Total Profit | AG1: % Margin
A2: Greece | B2: Louise | C2: 1348418.1 | D2: 204775.34 | E2: 0.15186338 | F2: 1671021.3 | G2: 254298.99 | H2: 0.15218178 | I2: 1698230.3 | J2: 1328070.8 | K2: 1501950.6 | L2: 1567569.8 | M2: 2104896.1 | Q2: 298948.72 | R2: 306208.71 | S2: 268511.22 | T2: 425100.79 | U2: 954907.05 | Y2: 0.17603544 | Z2: 0.23056655 | AA2: 0.17877501 | AB2: 0.27118461 | AC2: 0.45365995 | AE2: 11220157 | AF2: 2712750.8 | AG2: 0.24177477
A3: Spain | B3: Louise | C3: 869313.47 | D3: 1112376.1 | E3: 1.279603 | F3: 1119839.3 | G3: 1220338.9 | H3: 1.0897447 | I3: 968663.76 | J3: 822958.95 | K3: 1357231.5 | L3: 981591.34 | M3: 772386 | Q3: 1238331.4 | R3: 1355477.1 | S3: 1367922.8 | T3: 753131.19 | U3: 807307.21 | Y3: 1.2783914 | Z3: 1.6470774 | AA3: 1.0078772 | AB3: 0.76725533 | AC3: 1.0452121 | AE3: 6891984.3 | AF3: 7854884.7 | AG3: 1.1397131
A4: Louise Overall | C4: =SUM(C2:C3) -> 2217731.6 | D4: =SUM(D2:D3) -> 1317151.4 | E4: =D4/C4 -> 0.59391832 | F4: =SUM(F2:F3) -> 2790860.6 | G4: =SUM(G2:G3) -> 1474637.9 | H4: =G4/F4 -> 0.52838107 | I4: =SUM(I2:I3) -> 2666894.1 | J4: =SUM(J2:J3) -> 2151029.8 | K4: =SUM(K2:K3) -> 2859182.1 | L4: =SUM(L2:L3) -> 2549161.1 | M4: =SUM(M2:M3) -> 2877282.1 | Q4: =SUM(Q2:Q3) -> 1537280.1 | R4: =SUM(R2:R3) -> 1661685.8 | S4: =SUM(S2:S3) -> 1636434 | T4: =SUM(T2:T3) -> 1178232 | U4: =SUM(U2:U3) -> 1762214.3 | Y4: =Q4/I4 -> 0.57643089 | Z4: =R4/J4 -> 0.7725071 | AA4: =S4/K4 -> 0.5723434 | AB4: =T4/L4 -> 0.46220381 | AC4: =U4/M4 -> 0.61245795 | AE4: =SUM(AE2:AE3) -> 18112141 | AF4: =SUM(AF2:AF3) -> 10567635 | AG4: =AF4/AE4 -> 0.58345589
A5: Germany | B5: Luca | C5: 689392.21 | D5: 90575.727 | E5: 0.1313849 | F5: 874333.08 | G5: 69120.558 | H5: 0.079055179 | I5: 633817.21 | J5: 848412.21 | K5: 1299380.2 | L5: 1110479.7 | M5: 1919223.4 | Q5: 54206.657 | R5: 243255.91 | S5: 224595.89 | T5: 135560.24 | U5: 216728.3 | Y5: 0.085524116 | Z5: 0.28671901 | AA5: 0.17284848 | AB5: 0.12207358 | AC5: 0.112925 | AE5: 7375038 | AF5: 1034043.3 | AG5: 0.14020854
A6: France | B6: Luca | C6: 1290923.8 | D6: 157666.88 | E6: 0.12213493 | F6: 1157762.1 | G6: 136107.34 | H6: 0.11756071 | I6: 389072.31 | J6: 843019.2 | K6: 596988.12 | L6: 487012.9 | M6: 748452.82 | Q6: 97409.897 | R6: 109734.36 | S6: 122776.52 | T6: 76885.23 | U6: 144509.66 | Y6: 0.25036451 | Z6: 0.13016828 | AA6: 0.2056599 | AB6: 0.15787103 | AC6: 0.19307785 | AE6: 5513231.3 | AF6: 845089.89 | AG6: 0.15328395
A7: Italy | B7: Luca | C7: 699480.78 | D7: 129956.12 | E7: 0.18578941 | F7: 702747.14 | G7: 1626794.7 | H7: 2.3149076 | I7: 778492.87 | J7: 345734.45 | K7: 746345.05 | L7: 385516.58 | M7: 452901.31 | Q7: 580317.25 | R7: 288550.55 | S7: 326500.82 | T7: 361160.14 | U7: 289965.27 | Y7: 0.74543682 | Z7: 0.83460167 | AA7: 0.43746632 | AB7: 0.93682129 | AC7: 0.64023942 | AE7: 4111218.2 | AF7: 3603244.9 | AG7: 0.87644214
A8: AUSTRIA | B8: Luca | C8: 112968.55 | D8: 3911.56 | E8: 0.034625212 | F8: 117904.44 | G8: 15547.54 | H8: 0.1318656 | I8: 92012.96 | J8: 246387.05 | K8: 38628.2 | L8: 209783.88 | M8: 111545.29 | Q8: 5821.51 | R8: 9357.85 | S8: 1068.21 | T8: 11227.12 | U8: 7018.24 | Y8: 0.06326837 | Z8: 0.037980283 | AA8: 0.027653631 | AB8: 0.053517553 | AC8: 0.0629183 | AE8: 929230.37 | AF8: 53952.03 | AG8: 0.058060984
A9: Luca Overall | C9: =SUM(C5:C8) -> 2792765.3 | D9: =SUM(D5:D8) -> 382110.29 | E9: =D9/C9 -> 0.13682148 | F9: =SUM(F5:F8) -> 2852746.8 | G9: =SUM(G5:G8) -> 1847570.1 | H9: =G9/F9 -> 0.64764604 | I9: =SUM(I5:I8) -> 1893395.4 | J9: =SUM(J5:J8) -> 2283552.9 | K9: =SUM(K5:K8) -> 2681341.6 | L9: =SUM(L5:L8) -> 2192793.1 | M9: =SUM(M5:M8) -> 3232122.8 | Q9: =SUM(Q5:Q8) -> 737755.31 | R9: =SUM(R5:R8) -> 650898.67 | S9: =SUM(S5:S8) -> 674941.44 | T9: =SUM(T5:T8) -> 584832.73 | U9: =SUM(U5:U8) -> 658221.47 | Y9: =Q9/I9 -> 0.38964673 | Z9: =R9/J9 -> 0.2850377 | AA9: =S9/K9 -> 0.25171781 | AB9: =T9/L9 -> 0.26670676 | AC9: =U9/M9 -> 0.2036499 | AE9: =SUM(AE5:AE8) -> 17928718 | AF9: =SUM(AF5:AF8) -> 5536330.1 | AG9: =AF9/AE9 -> 0.30879676
A10: BELGIUM | B10: Manisha | C10: 565878.71 | D10: 43869.88 | E10: 0.077525235 | F10: 334443.8 | G10: 31337.35 | H10: 0.093699898 | I10: 348441.23 | J10: 437652.65 | K10: 264467.18 | L10: 454879.04 | M10: 416539.09 | Q10: 39180.903 | R10: 45642.36 | S10: 22343.35 | T10: 38409.76 | U10: 30916.61 | Y10: 0.11244623 | Z10: 0.10428901 | AA10: 0.084484396 | AB10: 0.084439503 | AC10: 0.07422259 | AE10: 2822301.7 | AF10: 251700.21 | AG10: 0.089182603
A11: Portugal | B11: Manisha | C11: 185239.91 | D11: 9316.75 | E11: 0.050295587 | F11: 347838.17 | G11: 39869.23 | H11: 0.11462005 | I11: 313794.71 | J11: 500964.01 | K11: 329070.9 | L11: 316846.67 | M11: 350975.54 | Q11: 27554.45 | R11: 51581.96 | S11: 34022.22 | T11: 28164.36 | U11: 33021.44 | Y11: 0.087810435 | Z11: 0.1029654 | AA11: 0.10338872 | AB11: 0.088889557 | AC11: 0.094084733 | AE11: 2344729.9 | AF11: 223530.41 | AG11: 0.095333117
A12: Ireland | B12: Manisha | C12: 106570.25 | D12: 37231.05 | E12: 0.34935688 | F12: 226334.75 | G12: 39325.23 | H12: 0.17374809 | I12: 154125.27 | J12: 174009.29 | K12: 291469.66 | L12: 164044.43 | M12: 256625.49 | Q12: 12121.79 | R12: 26002.74 | S12: 34797.7 | T12: 44610.84 | U12: 29927.63 | Y12: 0.078648946 | Z12: 0.14943306 | AA12: 0.11938704 | AB12: 0.27194364 | AC12: 0.11661987 | AE12: 1373179.1 | AF12: 224016.98 | AG12: 0.16313748
A13: Netherland | B13: Manisha | C13: 56810.73 | D13: 9372.52 | E13: 0.16497799 | F13: 174389.27 | G13: 72887.09 | H13: 0.41795628 | I13: 102890.18 | J13: 59261.72 | K13: 16707.14 | L13: 201000.12 | M13: 115453.22 | Q13: 17631.05 | R13: 4226.3 | S13: 1962.41 | T13: 17589.23 | U13: 24852.82 | Y13: 0.17135795 | Z13: 0.071315851 | AA13: 0.11745936 | AB13: 0.087508555 | AC13: 0.21526312 | AE13: 726512.38 | AF13: 148521.42 | AG13: 0.20443068
A14: Norway | B14: Manisha | C14: 52537.67 | D14: 2682.11 | E14: 0.051051179 | F14: 16333.8 | G14: 1671.1 | H14: 0.10230932 | I14: 33326.62 | J14: 44666.55 | K14: 30574.3 | L14: 43998.88 | Q14: 1937.42 | R14: 3993.53 | S14: 3736.5 | T14: 3802.1 | U14: 0 | Y14: 0.058134308 | Z14: 0.089407622 | AA14: 0.12221048 | AB14: 0.086413563 | AC14: 0 | AE14: 221437.82 | AF14: 17822.76 | AG14: 0.080486522
A15: Manisha Overall | C15: =SUM(C10:C14) -> 967037.27 | D15: =SUM(D10:D14) -> 102472.31 | E15: =D15/C15 -> 0.10596521 | F15: =SUM(F10:F14) -> 1099339.8 | G15: =SUM(G10:G14) -> 185090 | H15: =G15/F15 -> 0.16836469 | I15: =SUM(I10:I14) -> 952578.01 | J15: =SUM(J10:J14) -> 1216554.2 | K15: =SUM(K10:K14) -> 932289.18 | L15: =SUM(L10:L14) -> 1180769.1 | M15: =SUM(M10:M14) -> 1139593.3 | Q15: =SUM(Q10:Q14) -> 98425.613 | R15: =SUM(R10:R14) -> 131446.89 | S15: =SUM(S10:S14) -> 96862.18 | T15: =SUM(T10:T14) -> 132576.29 | U15: =SUM(U10:U14) -> 118718.5 | Y15: =Q15/I15 -> 0.10332551 | Z15: =R15/J15 -> 0.10804853 | AA15: =S15/K15 -> 0.10389714 | AB15: =T15/L15 -> 0.1122796 | AC15: =U15/M15 -> 0.1041762 | AE15: =SUM(AE10:AE14) -> 7488160.9 | AF15: =SUM(AF10:AF14) -> 865591.78 | AG15: =AF15/AE15 -> 0.11559471
A16: CZECH REPUBLIC | B16: Raffaella | C16: 223714.27 | D16: 46112.63 | E16: 0.20612288 | F16: 551042.65 | G16: 82877.4 | H16: 0.15040106 | I16: 567255.15 | J16: 462186.74 | K16: 376598.21 | L16: 339443.82 | M16: 228085.77 | Q16: 100039.27 | R16: 111510.59 | S16: 63744.68 | T16: 47326.69 | U16: 38644.37 | Y16: 0.17635674 | Z16: 0.24126739 | AA16: 0.16926443 | AB16: 0.13942422 | AC16: 0.16942911 | AE16: 2748326.6 | AF16: 490255.63 | AG16: 0.17838332
A17: Romania | B17: Raffaella | C17: 336338.56 | D17: 52520.12 | E17: 0.15615254 | F17: 418981.91 | G17: 59643.33 | H17: 0.142353 | I17: 234450.81 | J17: 423738.2 | K17: 400099.48 | L17: 220333.99 | M17: 332719.54 | Q17: 48836.63 | R17: 101000.43 | S17: 44988.81 | T17: 23395.51 | U17: 39895.78 | Y17: 0.20830224 | Z17: 0.23835573 | AA17: 0.11244406 | AB17: 0.10618203 | AC17: 0.11990814 | AE17: 2366662.5 | AF17: 370280.61 | AG17: 0.15645687
A18: BULGARIA | B18: Raffaella | C18: 99498.57 | D18: 10798.51 | E18: 0.1085293 | F18: 224850.44 | G18: 18667.36 | H18: 0.08302123 | I18: 83351.22 | J18: 249448.26 | K18: 179216.94 | L18: 275950.48 | M18: 140532.5 | Q18: 4588.13 | R18: 16763.5 | S18: 12713.93 | T18: 16744.42 | U18: 10355.21 | Y18: 0.055045745 | Z18: 0.067202313 | AA18: 0.070941564 | AB18: 0.060679075 | AC18: 0.073685518 | AE18: 1252848.4 | AF18: 90631.06 | AG18: 0.072340005
A19: SLOVEKIA | B19: Raffaella | C19: 73053.9 | D19: 1498.33 | E19: 0.020509925 | F19: 45401.3 | G19: 1331.33 | H19: 0.02932361 | I19: 84981.08 | J19: 110704.08 | K19: 91250.3 | L19: 68344.15 | M19: 82738.37 | Q19: 2245.94 | R19: 2775.93 | S19: 3410.43 | T19: 3045.13 | U19: 4462.57 | Y19: 0.026428706 | Z19: 0.025075228 | AA19: 0.037374452 | AB19: 0.044555825 | AC19: 0.053935919 | AE19: 556473.18 | AF19: 18769.66 | AG19: 0.033729676
A20: Poland | B20: Raffaella | C20: 9105 | D20: 4778 | E20: 0.52476661 | F20: 132859.78 | G20: 34424.26 | H20: 0.25910219 | I20: 152526.48 | J20: 58890.42 | K20: 47394.17 | L20: 43426 | M20: 79047.98 | Q20: 23074.4 | R20: 29558.48 | S20: 27862.36 | T20: 20600.2 | U20: 16710.82 | Y20: 0.15128127 | Z20: 0.5019234 | AA20: 0.58788581 | AB20: 0.4743748 | AC20: 0.21140097 | AE20: 523249.83 | AF20: 157008.52 | AG20: 0.30006416
A21: Hungary | B21: Raffaella | C21: 61919.56 | D21: 12601.54 | E21: 0.20351469 | F21: 57670.46 | G21: 7257.89 | H21: 0.12585109 | I21: 64466.79 | J21: 88777.79 | K21: 28039.54 | L21: 35702 | M21: 63773.95 | Q21: 2763.4 | R21: 3752.34 | S21: 1401.35 | T21: 1919.05 | U21: 4594.29 | Y21: 0.042865482 | Z21: 0.042266653 | AA21: 0.049977639 | AB21: 0.053751891 | AC21: 0.07204023 | AE21: 400350.09 | AF21: 34289.86 | AG21: 0.085649687
A22: Republic of Lithuania | B22: Raffaella | C22: 3319 | D22: 846 | E22: 0.25489605 | F22: 61177.6 | G22: 11276.6 | H22: 0.18432564 | I22: 75704.95 | J22: 46539.73 | K22: 53117.4 | L22: 21231.83 | M22: 110265.92 | Q22: 4233.39 | R22: 5247.45 | S22: 4490.2 | T22: 18499.81 | U22: 24089.1 | Y22: 0.055919593 | Z22: 0.11275205 | AA22: 0.084533505 | AB22: 0.87132433 | AC22: 0.21846369 | AE22: 371356.43 | AF22: 68682.55 | AG22: 0.18495048
A23: SLOVENIA | B23: Raffaella | C23: 21028.32 | D23: 1737.1 | E23: 0.082607645 | F23: 15714.72 | G23: 874.5 | H23: 0.055648462 | I23: 13432.47 | J23: 23852.26 | K23: 43224.72 | L23: 32082.9 | M23: 115147.84 | Q23: 831.78 | R23: 1192.38 | S23: 8109.66 | T23: 1363 | U23: 10422.8 | Y23: 0.061923086 | Z23: 0.049990232 | AA23: 0.18761625 | AB23: 0.042483691 | AC23: 0.090516678 | AE23: 264483.23 | AF23: 24531.22 | AG23: 0.092751514
A24: Latvia | B24: Raffaella | C24: 10813.8 | D24: 1039.3 | E24: 0.096108676 | F24: 67248.59 | G24: 3206.13 | H24: 0.047675795 | I24: 8758.75 | J24: 23701.38 | K24: 30306.79 | L24: 24618.6 | M24: 43855.67 | Q24: 276.85 | R24: 5742.82 | S24: 32077.48 | T24: 20540.8 | U24: 35613.74 | Y24: 0.031608392 | Z24: 0.24229897 | AA24: 1.0584255 | AB24: 0.83436101 | AC24: 0.81206695 | AE24: 209303.58 | AF24: 98497.12 | AG24: 0.47059453
A25: Croatia | B25: Raffaella | C25: 580.5 | D25: 87 | E25: 0.1498708 | H25: 0 | K25: 580.5 | L25: 1147.5 | M25: 1288.3 | S25: 114 | T25: 239 | U25: 268.7 | Y25: 0 | Z25: 0 | AA25: 0.19638243 | AB25: 0.20827887 | AC25: 0.20856943 | AE25: 3596.8 | AF25: 708.7 | AG25: 0.19703625
A26: Raffaella Overall | C26: =SUM(C16:C25) -> 839371.48 | D26: =SUM(D16:D25) -> 132018.53 | E26: =D26/C26 -> 0.1572826 | F26: =SUM(F16:F25) -> 1574947.5 | G26: =SUM(G16:G25) -> 219558.8 | H26: =G26/F26 -> 0.13940706 | I26: =SUM(I16:I25) -> 1284927.7 | J26: =SUM(J16:J25) -> 1487838.9 | K26: =SUM(K16:K25) -> 1249828 | L26: =SUM(L16:L25) -> 1062281.3 | M26: =SUM(M16:M25) -> 1197455.8 | Q26: =SUM(Q16:Q25) -> 186889.79 | R26: =SUM(R16:R25) -> 277543.92 | S26: =SUM(S16:S25) -> 198912.9 | T26: =SUM(T16:T25) -> 153673.61 | U26: =SUM(U16:U25) -> 185057.38 | Y26: =Q26/I26 -> 0.14544771 | Z26: =R26/J26 -> 0.18654165 | AA26: =S26/K26 -> 0.15915221 | AB26: =T26/L26 -> 0.14466377 | AC26: =U26/M26 -> 0.15454213 | AE26: =SUM(AE16:AE25) -> 8696650.7 | AF26: =SUM(AF16:AF25) -> 1353654.9 | AG26: =AF26/AE26 -> 0.15565244
A27: All Buyer Overall | C27: 6816905.7 | D27: 1933752.6 | F27: 8317894.6 | G27: 3726856.9 | I27: 6797795.2 | J27: 7138975.8 | K27: 7722640.9 | L27: 6985004.6 | M27: 8446454 | Q27: 2560350.9 | R27: 2721575.2 | S27: 2607150.5 | T27: 2049314.6 | U27: 2724211.6 | AE27: 52225671 | AF27: 18323212 | AG27: =AF27/AE27 -> 0.35084685

Sheet New License
A1: Country | B1: Buyer | C1: Lax Part No | D1: Description | E1: Country | F1: Granted Date | G1: Buying Comments | H1: Remarks
A2: France | B2: Luca | C2: L1503 | D2: Ontozry 200mg Tabs 28 | E2: France | F2: 46062 | G2: In Labelling / On Order | H2: No Stock Received | J2: CountryWise Bifurcation | M2: Status Till Jul'26
A3: Ireland | B3: Manisha | D3: Vagifem 10 micrograms vaginal tablets | E3: Ireland | F3: 46066 | G3: Price Issue | H3: No Stock Received | J3: Country | K3: No of Products | M3: Remarks | N3: No of Products
A4: Spain | B4: Louise | C4: 5028 | D4: Cholestagel 625mg Tablets 180 | E4: Spain | F4: 46079 | G4: Price Issue | H4: No Stock Received | J4: Austria | K4: 2 | M4: MAH Objection | N4: 0
A5: Spain | B5: Louise | C5: 360 | D5: Ontozry 50mg Tabs 28 | E5: Spain | F5: 46101 | G5: In Labelling / On Order | H5: No Stock Received | J5: BULGARIA | K5: 1 | M5: Price Issue | N5: 3
A6: Spain | B6: Louise | C6: 5029 | D6: Wynzora cream 0.5mg/g 60 | E6: Spain | F6: 46086 | G6: In Labelling / On Order | H6: No Stock Received | J6: Czech Republic | K6: 2 | M6: Variation | N6: 3
A7: Spain | B7: Louise | C7: 5040 | D7: Vesicare oral suspension 1mg/ml 1's | E7: Spain | F7: 46101 | G7: In Labelling / On Order | H7: No Stock Received | J7: France | K7: 9 | M7: Not On Order | N7: 4
A8: Greece | B8: Louise | C8: 163 | D8: Bicalutamide 50mg Tablets 28 | E8: Greece | F8: 46090 | G8: In Labelling / On Order | H8: No Stock Received | J8: France | K8: 2 | M8: Awaiting MAH | N8: 7
A9: France | B9: Luca | C9: L1515 | D9: Ontozry 150mg Tabs 28 | E9: France | F9: 46106 | G9: In Labelling / On Order | H9: No Stock Received | J9: Germany | K9: 2 | M9: In Labelling / On Order | N9: 26
A10: Spain | B10: Louise | C10: L7128 | D10: Lenzetto transdermal spray 1.53mg 1's | E10: Spain | F10: 46108 | G10: Not On Order | H10: No Stock Received | J10: Greece | K10: 16 | M10: Stock Received | N10: 32
A11: Poland | B11: Raffaella | C11: 1101 | D11: XONVEA 10mg/10mg tablets 20 | E11: Poland | F11: 46106 | G11: In Labelling / On Order | H11: No Stock Received | J11: Holland | K11: 2 | M11: Grand Total | N11: 75
A12: Italy | B12: Luca | C12: 5248 | D12: Stalevo® 75 mg/18,75 mg/200 mg compresse rivestite con film | E12: Italy | F12: 46121 | G12: In Labelling / On Order | H12: No Stock Received | J12: Ireland | K12: 5
A13: Germany | B13: Luca | C13: 5296 | D13: Flutiform 250mcg/dose & 10mcg/dose Inhaler 120doses | E13: Germany | F13: 46142 | G13: In Labelling / On Order | H13: No Stock Received | J13: Italy | K13: 2
A14: Greece | B14: Louise | C14: 6813 | D14: TOSTRAN 2% Gel x 60g | E14: Greece | F14: 46126 | G14: Variation | H14: No Stock Received | J14: Lithuania | K14: 1
A15: Spain | B15: Louise | C15: 8500 | D15: Elvanse Capsules 50mg 28s | E15: Spain | F15: 46134 | G15: Variation | H15: No Stock Received | J15: Netherlands | K15: 8
A16: Spain | B16: Louise | D16: Vazkepa® 998 mg cápsulas blandas | E16: Spain | F16: 46113 | G16: Not On Order | H16: No Stock Received | J16: Poland | K16: 1
A17: Austria | B17: Luca | D17: Seroquel XL 200 mg prolonged-release tablets | E17: Austria | F17: 46170 | G17: MAH Objection | H17: No Stock Received | J17: Portugal | K17: 3
A18: Austria | B18: Luca | D18: Seroquel XL 300 mg prolonged-release tablets | E18: Austria | F18: 46170 | G18: MAH Objection | H18: No Stock Received | J18: ROMANIA | K18: 5
A19: France | B19: Luca | C19: M0006 | D19: TRULICITY Solution for Injection PF Pen 0.75mg x 4's | E19: France | F19: 46156 | G19: Not On Order | H19: No Stock Received | J19: Spain | K19: 14
A20: Germany | B20: Luca | C20: 2366 | D20: Xadago tablets f/c 100 mg 30s | E20: Germany | F20: 46148 | G20: Price Issue | H20: No Stock Received | J20: Grand Total | K20: 75
A21: Greece | B21: Louise | C21: 5045 | D21: Neupro 1 mg/24 h transdermal patch | E21: Greece | F21: 46161 | G21: Not On Order | H21: No Stock Received
A22: Lithuania | B22: Raffaella | C22: 5175C | D22: Creon 25000 Gastroresistant Capsules 50 | E22: Lithuania | F22: 46162 | G22: In Labelling / On Order | H22: No Stock Received
A23: Ireland | B23: Manisha | C23: 5670B | D23: CLOPIXOL DEPOT INJECTION 200 MG/ML AMP 1ML | E23: Ireland | F23: 46157 | G23: In Labelling / On Order | H23: No Stock Received
A24: Romania | B24: Raffaella | C24: M0310 | D24: TRULICITY Solution for Injection PF Pens 1.5mg x 4's | E24: Romania | F24: 46156 | G24: In Labelling / On Order | H24: No Stock Received
A25: Spain | B25: Louise | C25: 5045 | D25: Neupro 1 mg/24 h transdermal patch | E25: Spain | F25: 46160 | G25: Not On Order | H25: No Stock Received
A26: Romania | B26: Raffaella | C26: 1237 | D26: Symbicort 200mcg/6mcg Pressurised inhaler 120 doses | E26: Romania | F26: 46195 | G26: In Labelling / On Order | H26: No Stock Received
A27: Portugal | B27: Manisha | C27: 5426 | D27: Ropinirole 2mg Filmcoated Tablets 84 | E27: Portugal | F27: 46184 | G27: In Labelling / On Order | H27: No Stock Received
A28: Netherlands | B28: Manisha | C28: 5591 | D28: Tranylcypromine 10mg Film-coated Tablets | E28: Netherlands | F28: 46184 | G28: In Labelling / On Order | H28: No Stock Received
A29: Greece | B29: Louise | C29: L0239J | D29: Canesten 500mg Pessary | E29: Greece | F29: 46177 | G29: In Labelling / On Order | H29: No Stock Received
A30: Greece | B30: Louise | C30: M0108 | D30: NovoRapid 100 units/ml solution for injection in vial | E30: Greece | F30: 46197 | G30: In Labelling / On Order | H30: No Stock Received
A31: Ireland | B31: Manisha | C31: 5458 | D31: Oestrogel (0.06%) 80g Pump Pack 64 | E31: Ireland | F31: 46185 | G31: In Labelling / On Order | H31: No Stock Received
A32: Ireland | B32: Manisha | C32: 2548B | D32: BuTrans 15 micrograms/hour transdermal patch | E32: Ireland | F32: 46178 | G32: In Labelling / On Order | H32: No Stock Received
A33: Ireland | B33: Manisha | C33: 5727A | D33: Resolor 2mg film-coated tablets | E33: Ireland | F33: 46195 | G33: Price Issue | H33: No Stock Received
A34: Czech Republic | B34: Raffaella | C34: 5337A | D34: Tresiba Flextouch 200u/ml Injection 3mlx3 | E34: Czech Republic | F34: 46178 | G34: In Labelling / On Order | H34: No Stock Received
A35: Netherlands | B35: Manisha | C35: 170 | D35: BuTrans 5mcg/hr transdermal patch | E35: Netherlands | F35: 46178 | G35: In Labelling / On Order | H35: No Stock Received
A36: Netherlands | B36: Manisha | C36: 294 | D36: BuTrans 10mcg/hr transdermal patch | E36: Netherlands | F36: 46178 | G36: In Labelling / On Order | H36: No Stock Received
A37: Netherlands | B37: Manisha | C37: 5458 | D37: Oestrogel Pump-Pack 750 micrograms/actuation Gel | E37: Netherlands | F37: 46203 | G37: In Labelling / On Order | H37: No Stock Received
A38: Netherlands | B38: Manisha | C38: 6031 | D38: BuTrans 20mcg/hr transdermal patch | E38: Netherlands | F38: 46178 | G38: In Labelling / On Order | H38: No Stock Received
A39: Netherlands | B39: Manisha | C39: 6001B | D39: Monuril 3g Granules Sachets 3g | E39: Netherlands | F39: 46192 | G39: In Labelling / On Order | H39: No Stock Received
A40: Greece | B40: Louise | C40: M0310 | D40: TRULICITY Solution for Injection PF Pens 1.5mg x 4's | E40: Greece | F40: 46185 | G40: In Labelling / On Order | H40: No Stock Received
...

Sheet Sales
A1: AVG
A2: Regular Lines | E2: Jan to Aug New Lines | I2: Overall PI
A3: Month | B3: Sales | C3: Profit | D3: % | E3: Sales | F3: Profit | G3: % | I3: Month | J3: Sales | K3: Profit | L3: %
A4: Jan | B4: 430351.95 | C4: 41838.883 | D4: 0.097220155 | E4: 25377.101 | F4: 2118.5485 | G4: 0.083482684 | I4: Jan | J4: =B4+E4 -> 455729.05 | K4: =C4+F4 -> 43957.432 | L4: =K4/J4 -> 0.096455189
A5: Feb | B5: 423523.45 | C5: 43051.943 | D5: 0.10165185 | E5: 36198.542 | F5: 2065.156 | G5: 0.057050806 | I5: Feb | J5: =B5+E5 -> 459721.99 | K5: =C5+F5 -> 45117.099 | L5: =K5/J5 -> 0.098139962
A6: Mar | B6: 453932.28 | C6: 47647.482 | D6: 0.10496606 | E6: 45983.651 | F6: 2906.8761 | G6: 0.063215426 | I6: Mar | J6: =B6+E6 -> 499915.93 | K6: =C6+F6 -> 50554.358 | L6: =K6/J6 -> 0.10112572
A7: Apr | B7: 472463.06 | C7: 55662.929 | D7: 0.11781435 | E7: 50116.838 | F7: 3088.1085 | G7: 0.061618183 | I7: Apr | J7: =B7+E7 -> 522579.9 | K7: =C7+F7 -> 58751.038 | L7: =K7/J7 -> 0.11242499
A8: May | B8: 483690.46 | C8: 58984.246 | D8: 0.12194627 | E8: 64766.922 | F8: 4655.3074 | G8: 0.071877854 | I8: May | J8: =B8+E8 -> 548457.39 | K8: =C8+F8 -> 63639.554 | L8: =K8/J8 -> 0.11603373
A9: June | B9: 466213.94 | C9: 57529.83 | D9: 0.12339792 | E9: 67126.459 | F9: 5297.5973 | G9: 0.07891966 | I9: June | J9: =B9+E9 -> 533340.4 | K9: =C9+F9 -> 62827.427 | L9: =K9/J9 -> 0.11779986
A10: July | B10: 482720.96 | C10: 54189.387 | D10: 0.1122582 | E10: 74922.156 | F10: 7609.4641 | G10: 0.10156494 | I10: July | J10: =B10+E10 -> 557643.12 | K10: =C10+F10 -> 61798.851 | L10: =K10/J10 -> 0.11082151
A11: Aug | B11: 495741.37 | C11: 55291.387 | D11: 0.11153273 | E11: 72208.684 | F11: 9952.0118 | G11: 0.13782292 | I11: Aug | J11: =B11+E11 -> 567950.06 | K11: =C11+F11 -> 65243.399 | L11: =K11/J11 -> 0.11487524

Sheet 15% PCA
E1: Daily | H1: MTD | K1: PCA Achievement
A2: catalog_no | B2: Part_description | C2: Category | D2: Current Stock | E2: Daily PCA | F2: QTY | G2: Diff | H2: 15% PCA | I2: MTD QTY | J2: Diff | K2: MTD % | L2: Daily %
A3: 5282A | B3: Janumet 50mg/1g Tablets 56 | C3: Parallel Import | D3: 850 | E3: 5 | F3: -1 | G3: =F3-E3 -> -6 | H3: 100 | I3: 895 | J3: =I3-H3 -> 795 | K3: =I3/H3 -> 8.95 | L3: =F3/E3 -> -0.2
A4: 1110F | B4: Valsartan 160mg / HCZ12.5mg Tabs 28 (PI) | C4: Generic to PI | D4: 0 | E4: 10 | F4: 0 | G4: =F4-E4 -> -10 | H4: 200 | I4: 0 | J4: =I4-H4 -> -200 | K4: =I4/H4 -> 0 | L4: =F4/E4 -> 0
A5: 5481A | B5: Dosulepin 75mg Tabs PI - 28s | C5: Generic to PI | D5: 0 | E5: 66 | F5: 0 | G5: =F5-E5 -> -66 | H5: 1320 | I5: 2 | J5: =I5-H5 -> -1318 | K5: =I5/H5 -> 0.0015151515 | L5: =F5/E5 -> 0
A6: 1062 | B6: Calcipotriol 50mcg Ointment 30g (PI) | C6: Generic to PI | D6: 0 | E6: 72 | F6: 0 | G6: =F6-E6 -> -72 | H6: 1440 | I6: 5 | J6: =I6-H6 -> -1435 | K6: =I6/H6 -> 0.0034722222 | L6: =F6/E6 -> 0
A7: 5390 | B7: Lamictal 200mg Tablets 30 | C7: Parallel Import | D7: 0 | E7: 23 | F7: 0 | G7: =F7-E7 -> -23 | H7: 460 | I7: 2 | J7: =I7-H7 -> -458 | K7: =I7/H7 -> 0.0043478261 | L7: =F7/E7 -> 0
A8: 0739 | B8: Lamotrigine 100mg Dispersible Tablets 56 (PI) | C8: Generic to PI | D8: 597 | E8: 57 | F8: 0 | G8: =F8-E8 -> -57 | H8: 1140 | I8: 7 | J8: =I8-H8 -> -1133 | K8: =I8/H8 -> 0.0061403509 | L8: =F8/E8 -> 0
A9: 4989D | B9: Co-Trimoxazole 40/200mg/5ml Oral Suspension SF 100ml | C9: Generic to PI | D9: 299 | E9: 8 | F9: 0 | G9: =F9-E9 -> -8 | H9: 160 | I9: 1 | J9: =I9-H9 -> -159 | K9: =I9/H9 -> 0.00625 | L9: =F9/E9 -> 0
A10: 5963N | B10: Arcoxia 90mg Tablets 14 | C10: Parallel Import | D10: 0 | E10: 2 | F10: 0 | G10: =F10-E10 -> -2 | H10: 40 | I10: 1 | J10: =I10-H10 -> -39 | K10: =I10/H10 -> 0.025 | L10: =F10/E10 -> 0
A11: 5578A | B11: Trileptal 300mg Tablets 50 | C11: Parallel Import | D11: 0 | E11: 2 | F11: 0 | G11: =F11-E11 -> -2 | H11: 40 | I11: 1 | J11: =I11-H11 -> -39 | K11: =I11/H11 -> 0.025 | L11: =F11/E11 -> 0
A12: 5680K | B12: Ropinirole Tablets 0.25mg 12 (PI) | C12: Generic to PI | D12: 0 | E12: 48 | F12: 0 | G12: =F12-E12 -> -48 | H12: 960 | I12: 29 | J12: =I12-H12 -> -931 | K12: =I12/H12 -> 0.030208333 | L12: =F12/E12 -> 0
A13: L6002 | B13: Nustendi tablets 180mg/10mg 28 | C13: Parallel Import | D13: 0 | E13: 404 | F13: 0 | G13: =F13-E13 -> -404 | H13: 8080 | I13: 297 | J13: =I13-H13 -> -7783 | K13: =I13/H13 -> 0.036757426 | L13: =F13/E13 -> 0
A14: 3654 | B14: Mefenamic Acid 500mg Tablets 30 | C14: Generic to PI | D14: 5 | E14: 150 | F14: 0 | G14: =F14-E14 -> -150 | H14: 3000 | I14: 137 | J14: =I14-H14 -> -2863 | K14: =I14/H14 -> 0.045666667 | L14: =F14/E14 -> 0
... A57: 5430C | B57: Utrogestan Vaginal 200mg Capsules (21) | C57: Parallel Import | D57: 260 | E57: 8 | F57: 35 | G57: =F57-E57 -> 27 | H57: 160 | I57: 640 | J57: =I57-H57 -> 480 | K57: =I57/H57 -> 4 | L57: =F57/E57 -> 4.375

Sheet Overstock
A1: Code | B1: Description | C1: Category | D1: Stock | E1: True Cost | F1: Stock Value | G1: No Of Days Stock
A2: 5119C | B2: Onbrez Inhaler 300mcg 30 Capsules+1 Inhaler | C2: Parallel Import | D2: 427 | E2: 19.46 | F2: 8309.42 | G2: 421
A3: 5679 | B3: Zyprexa 20mg Velotabs 28 | C3: Parallel Import | D3: 442 | E3: 31.29 | F3: 13830.18 | G3: 351
A4: 5193A | B4: CoDiovan 80mg/12.5mg Tablets 28 | C4: Parallel Import | D4: 421 | E4: 4.45 | F4: 1873.45 | G4: 136
A5: 5282B | B5: Januvia 25mg Tablets 28 | C5: Parallel Import | D5: 539 | E5: 11.5 | F5: 6198.5 | G5: 135
A6: 5213 | B6: Frumil 40mg/5mg Tablets 28 | C6: Parallel Import | D6: 6819 | E6: 3.61 | F6: 24616.59 | G6: 128
A7: 5855 | B7: Zyprexa 5mg Velotabs 28 | C7: Parallel Import | D7: 471 | E7: 9.03 | F7: 4253.13 | G7: 118
A8: 5613B | B8: Requip XL 8mg Tablets 28 | C8: Parallel Import | D8: 919 | E8: 19.69 | F8: 18095.11 | G8: 115
A9: D0396A | B9: FreeStyle Lite Testing Strips 50 | C9: Parallel Import | D9: 3981 | E9: 8.84 | F9: 35192.04 | G9: 104

Sheet Additional Watch Sales
I2: OVERALL
I4: Sales Analysis | R4: Sales Analysis - Removed Top 5 Profit
I5: Month | J5: Unique products | K5: Boxes | L5: AVG Sales | M5: AVG Profit | N5: Total Sales | O5: Total Profit | P5: Margin | R5: Month | S5: Unique products | T5: Boxes | U5: AVG Sales | V5: AVG Profit | W5: Total Sales | X5: Total Profit | Y5: Margin
I6: Feb | J6: 381 | K6: 339177 | L6: =N6/20 -> 316565.46 | M6: =O6/20 -> 32829.003 | N6: 6331309.2 | O6: 656580.06 | P6: =+O6/N6 -> 0.10370368 | R6: Feb | S6: 376 | T6: 327023 | U6: =W6/20 -> 288087.56 | V6: =X6/20 -> 24004.758 | W6: 5761751.1 | X6: 480095.16 | Y6: =+X6/W6 -> 0.083324522
I7: Mar | J7: 386 | K7: 397866 | L7: =N7/23 -> 329916.9 | M7: =O7/20 -> 40836.887 | N7: 7588088.7 | O7: 816737.74 | P7: =+O7/N7 -> 0.10763418 | R7: Mar | S7: 381 | T7: 383645 | U7: =W7/23 -> 297757.76 | V7: =X7/20 -> 31947.593 | W7: 6848428.5 | X7: 638951.86 | Y7: =+X7/W7 -> 0.093299048
I8: April | J8: 386 | K8: 446480 | L8: =N8/20 -> 367150.07 | M8: =O8/20 -> 43108.672 | N8: 7343001.4 | O8: 862173.44 | P8: =+O8/N8 -> 0.11741431 | R8: April | S8: 381 | T8: 436096 | U8: =W8/20 -> 338213.7 | V8: =X8/20 -> 33762.611 | W8: 6764273.9 | X8: 675252.22 | Y8: =+X8/W8 -> 0.099826268
I9: May | J9: 380 | K9: 423404 | L9: =N9/19 -> 389690.54 | M9: =O9/20 -> 46316.513 | N9: 7404120.2 | O9: 926330.26 | P9: =+O9/N9 -> 0.12511011 | R9: May | S9: 375 | T9: 411285 | U9: =W9/19 -> 354239.19 | V9: =X9/20 -> 36405.317 | W9: 6730544.5 | X9: 728106.35 | Y9: =+X9/W9 -> 0.10817941
I10: June | J10: 395 | K10: 437568 | L10: =N10/22 -> 368447.54 | M10: =O10/20 -> 51828.774 | N10: 8105846 | O10: 1036575.5 | P10: =+O10/N10 -> 0.12787999 | R10: June | S10: 390 | T10: 426174 | U10: =W10/22 -> 339946.23 | V10: =X10/20 -> 40214.483 | W10: 7478817.1 | X10: 804289.66 | Y10: =+X10/W10 -> 0.10754236
I11: July | J11: 451 | K11: 378098 | L11: =N11/22 -> 392869.36 | M11: =O11/20 -> 49372.754 | N11: 8643126 | O11: 987455.09 | P11: 0.11424745 | R11: July | S11: 443 | T11: 367439 | U11: =W11/22 -> 366829.5 | V11: =X11/20 -> 38847.561 | W11: 8070249 | X11: 776951.23 | Y11: 0.096273514
B14: Product Wise Bifurcation
B16: Sales Analysis (Regular Products) | K16: Sales Analysis - Removed Top 5 Profit (Regular Products) | T16: Sales Analysis (New Products)
B17: Month | C17: Unique products | D17: Boxes | E17: AVG Sales | F17: AVG Profit | G17: Total Sales | H17: Total Profit | I17: Margin | K17: Month | L17: Unique products | M17: Boxes | N17: AVG Sales | O17: AVG Profit | P17: Total Sales | Q17: Total Profit | R17: Margin | T17: Month | U17: Unique products | V17: Boxes | W17: AVG Sales | X17: AVG Profit | Y17: Total Sales | Z17: Total Profit | AA17: Margin
B18: Feb | C18: 351 | D18: 310056 | E18: =G18/20 -> 278613.7 | F18: =H18/20 -> 32621.801 | G18: 5572274 | H18: 652436.03 | I18: 0.11708614 | K18: Feb | L18: 344 | M18: 296790 | N18: =P18/20 -> 257378.69 | O18: =Q18/20 -> 22076.188 | P18: 5147573.8 | Q18: 441523.76 | R18: 0.085773178 | T18: Feb | U18: 25 | V18: 29556 | W18: =Y18/20 -> 15953.892 | X18: =Z18/20 -> 2065.561 | Y18: 319077.84 | Z18: 41311.22 | AA18: 0.12947066
B19: Mar | C19: 355 | D19: 352108 | E19: =G19/23 -> 300955.5 | F19: =H19/20 -> 39262.386 | G19: 6921976.4 | H19: 785247.73 | I19: 0.11344271 | K19: Mar | L19: 348 | M19: 336422 | N19: =P19/23 -> 274283.34 | O19: =Q19/20 -> 28583.91 | P19: 6308516.7 | Q19: 571678.21 | R19: 0.090620067 | T19: Mar | U19: 27 | V19: 46267 | W19: =Y19/23 -> 17629.223 | X19: =Z19/20 -> 3370.3075 | Y19: 405472.12 | Z19: 67406.15 | AA19: 0.16624115
B20: April | C20: 358 | D20: 394929 | E20: =G20/20 -> 298852.16 | F20: =H20/20 -> 40956.39 | G20: 5977043.2 | H20: 819127.8 | I20: 0.13704566 | K20: April | L20: 352 | M20: 383357 | N20: =P20/20 -> 276976.49 | O20: =Q20/20 -> 30012.414 | P20: 5539529.8 | Q20: 600248.28 | R20: 0.10835726 | T20: April | U20: 26 | V20: 52327 | W20: =Y20/20 -> 11563.398 | X20: =Z20/20 -> 3370.3075 | Y20: 231267.97 | Z20: 67406.15 | AA20: 0.2914634
B21: May | C21: 349 | D21: 370672 | E21: =G21/19 -> 308321.1 | F21: =H21/20 -> 44017.588 | G21: 5858100.9 | H21: 880351.77 | I21: 0.15027938 | K21: May | L21: 342 | M21: 355466 | N21: =P21/19 -> 280414.37 | O21: =Q21/20 -> 31397.49 | P21: 5327873 | Q21: 627949.8 | R21: 0.11786126 | T21: May | U21: 25 | V21: 53425 | W21: =Y21/19 -> 12840.582 | X21: =Z21/20 -> 4147.823 | Y21: 243971.05 | Z21: 82956.46 | AA21: 0.34002584
B22: June | C22: 356 | D22: 384155 | E22: =G22/22 -> 295908.13 | F22: =H22/20 -> 48267.767 | G22: 6509978.8 | H22: 965355.35 | I22: 0.14828856 | K22: June | L22: 349 | M22: 370620 | N22: =P22/22 -> 275813.53 | O22: =Q22/20 -> 33575.391 | P22: 6067897.6 | Q22: 671507.83 | R22: 0.11066565 | T22: June | U22: 31 | V22: 54297 | W22: =Y22/22 -> 24534.317 | X22: =Z22/20 -> 4633.3905 | Y22: 539754.97 | Z22: 92667.81 | AA22: 0.17168496
B23: July | C23: 361 | D23: 420696 | E23: =G23/22 -> 314105.85 | F23: =H23/20 -> 42034.375 | G23: 6910328.7 | H23: 840687.5 | I23: 0.12165666 | K23: July | L23: 354 | M23: 410543 | N23: =P23/22 -> 299730.31 | O23: =Q23/20 -> 31421.425 | P23: 6594066.7 | Q23: 628428.5 | R23: 0.095302114 | T23: July | U23: 32 | V23: 73382 | W23: =Y23/22 -> 28039.541 | X23: =Z23/20 -> 8185.438 | Y23: 616869.91 | Z23: 163708.76 | AA23: 0.2653862

Sheet Additional watch Purchase
E2: OVERALL
E4: Purchase Analysis | L4: Purchase Analysis - Removed Top 5
E5: Month | F5: Unique products | G5: Boxes | H5: Purchase Value | I5: Potential Profit | J5: Margin | L5: Month | M5: Unique products | N5: Boxes | O5: Purchase Value | P5: Potential Profit | Q5: Margin
E6: Feb | F6: 295 | G6: 418514.39 | H6: 8210000 | I6: 1699175 | J6: =+I6/H6 -> 0.20696407 | L6: Feb | M6: 292 | N6: 410551.89 | O6: 8162031.5 | P6: 984751.58 | Q6: =+P6/O6 -> 0.1206503
E7: Mar | F7: 260 | G7: 343636.91 | H7: 6700000 | I7: 1063643.7 | J7: =+I7/H7 -> 0.1587528 | L7: Mar | M7: 258 | N7: 340223.91 | O7: 6627463.3 | P7: 776968.22 | Q7: =+P7/O7 -> 0.11723463
E8: April | F8: 253 | G8: 297521.18 | H8: 7010000 | I8: 1140054.8 | J8: =+I8/H8 -> 0.16263263 | L8: April | M8: 251 | N8: 293708.18 | O8: 6943915.6 | P8: 818471.24 | Q8: =+P8/O8 -> 0.11786883
E9: May | F9: 268 | G9: 377950.98 | H9: 7630000 | I9: 1304619 | J9: =+I9/H9 -> 0.17098545 | L9: May | M9: 265 | N9: 372135.23 | O9: 7568451 | P9: 924932.31 | Q9: =+P9/O9 -> 0.12220893
E10: June | F10: 281 | G10: 336499.92 | H10: 6930000 | I10: 1153510.1 | J10: =+I10/H10 -> 0.16645167 | L10: June | M10: 278 | N10: 330230.67 | O10: 6804735.8 | P10: 820789.71 | Q10: =+P10/O10 -> 0.12062036
E11: July | F11: 319 | G11: 496145.71 | H11: 8446978.4 | I11: 2030463.7 | J11: =+I11/H11 -> 0.24037752 | L11: July | M11: =+F11-5 -> 314 | N11: 480227.71 | O11: 8340365 | P11: 1295944.4 | Q11: =+P11/O11 -> 0.15538222
B14: Product Wise Bifurcation
B16: Purchase Analysis (Regular Products) | I16: Purchase Analysis - Removed Top 5 (Regular Products) | P16: Purchase Analysis (New Products)
B17: Month | C17: Unique products | D17: Boxes | E17: Purchase Value | F17: Potential Profit | G17: Margin | I17: Month | J17: Unique products | K17: Boxes | L17: Purchase Value | M17: Potential Profit | N17: Margin | P17: Month | Q17: Unique products | R17: Boxes | S17: Purchase Value | T17: Potential Profit | U17: Margin
B18: Feb | C18: 279 | D18: 367568.06 | E18: 7055393 | F18: 1616962.7 | G18: 0.22918109 | I18: Feb | J18: 273 | K18: 345672.36 | L18: 6468748.1 | M18: 784284.86 | N18: 0.12124214 | P18: Feb | Q18: 16 | R18: 50946.333 | S18: 1017299.9 | T18: 80906.82 | U18: 0.079530943
B19: Mar | C19: 243 | D19: 294215.25 | E19: 5546326.8 | F19: 981990.41 | G19: 0.17705239 | I19: Mar | J19: 238 | K19: 281476.91 | L19: 5166717 | M19: 614441.36 | N19: 0.11892298 | P19: Mar | Q19: 17 | R19: 49421.667 | S19: 996797.81 | T19: 77882.45 | U19: 0.078132646
B20: April | C20: 230 | D20: 254854.52 | E20: 6181422.4 | F20: 1037936.2 | G20: 0.1679122 | I20: April | J20: 225 | K20: 243274.72 | L20: 5852920 | M20: 654815.95 | N20: 0.11187851 | P20: April | Q20: 23 | R20: 42666.667 | S20: 780542.79 | T20: 98694.21 | U20: 0.12644305
B21: May | C21: 238 | D21: 325821.86 | E21: 6323811.2 | F21: 1162311.8 | G21: 0.18379925 | I21: May | J21: 232 | K21: 314379.44 | L21: 6100277.3 | M21: 740707.8 | N21: 0.12142199 | P21: May | Q21: 30 | R21: 52129.121 | S21: 933522.83 | T21: 133483.6 | U21: 0.14298911
B22: June | C22: 253 | D22: 293587.58 | E22: 5744574.2 | F22: 1019523.3 | G22: 0.17747587 | I22: June | J22: 246 | K22: 281227.67 | L22: 5521600.1 | M22: 629816.79 | N22: 0.11406418 | P22: June | Q22: 28 | R22: 42912.333 | S22: 878155.92 | T22: 130182.13 | U22: 0.14824489
B23: July | C23: 280 | D23: 402727 | E23: 6958472 | F23: 1646964.9 | G23: 0.23668485 | I23: July | J23: 273 | K23: 377665 | L23: 6177057.7 | M23: 844908.83 | N23: 0.13678176 | P23: July | Q23: 35 | R23: 79258.71 | S23: 1321022.5 | T23: 274037.32 | U23: 0.20744335

Sheet Updated Summary
A1: OVERALL
A3: Purchase Analysis | H3: Purchase Analysis - Removed Top 5
A4: Month | B4: Unique products | C4: Boxes | D4: Purchase Value | E4: Potential Profit | F4: Margin | H4: Month | I4: Unique products | J4: Boxes | K4: Purchase Value | L4: Potential Profit | M4: Margin
A5: Feb | B5: 295 | C5: 418514.39 | D5: 8210000 | E5: 1699175 | F5: =+E5/D5 -> 0.20696407 | H5: Feb | I5: 292 | J5: 410551.89 | K5: 8162031.5 | L5: 984751.58 | M5: =+L5/K5 -> 0.1206503
A6: Mar | B6: 260 | C6: 343636.91 | D6: 6700000 | E6: 1063643.7 | F6: =+E6/D6 -> 0.1587528 | H6: Mar | I6: 258 | J6: 340223.91 | K6: 6627463.3 | L6: 776968.22 | M6: =+L6/K6 -> 0.11723463
A7: April | B7: 253 | C7: 297521.18 | D7: 7010000 | E7: 1140054.8 | F7: =+E7/D7 -> 0.16263263 | H7: April | I7: 251 | J7: 293708.18 | K7: 6943915.6 | L7: 818471.24 | M7: =+L7/K7 -> 0.11786883
A8: May | B8: 268 | C8: 377950.98 | D8: 7630000 | E8: 1304619 | F8: =+E8/D8 -> 0.17098545 | H8: May | I8: 265 | J8: 372135.23 | K8: 7568451 | L8: 924932.31 | M8: =+L8/K8 -> 0.12220893
A9: June | B9: 281 | C9: 336499.92 | D9: 6930000 | E9: 1153510.1 | F9: =+E9/D9 -> 0.16645167 | H9: June | I9: 278 | J9: 330230.67 | K9: 6804735.8 | L9: 820789.71 | M9: =+L9/K9 -> 0.12062036
A10: July | B10: 319 | C10: 496145.71 | D10: 8446978.4 | E10: 2030463.7 | F10: =+E10/D10 -> 0.24037752 | H10: July | I10: =+B10-5 -> 314 | J10: 480227.71 | K10: 8340365 | L10: 1295944.4 | M10: =+L10/K10 -> 0.15538222
A12: Sales Analysis | H12: Sales Analysis - Removed Top 5 Profit
A13: Month | B13: Unique products | C13: Boxes | D13: Sales Value | E13: Profit | F13: Margin | H13: Month | I13: Unique products | J13: Boxes | K13: Sales Value | L13: Profit | M13: Margin
A14: Feb | B14: 381 | C14: 339177 | D14: 6331309.2 | E14: 656580.06 | F14: =+E14/D14 -> 0.10370368 | H14: Feb | I14: 376 | J14: 327023 | K14: 5761751.1 | L14: 480095.16 | M14: =+L14/K14 -> 0.083324522
A15: Mar | B15: 386 | C15: 397866 | D15: 7588088.7 | E15: 816737.74 | F15: =+E15/D15 -> 0.10763418 | H15: Mar | I15: 381 | J15: 383645 | K15: 6848428.5 | L15: 638951.86 | M15: =+L15/K15 -> 0.093299048
A16: April | B16: 386 | C16: 446480 | D16: 7343001.4 | E16: 862173.44 | F16: =+E16/D16 -> 0.11741431 | H16: April | I16: 381 | J16: 436096 | K16: 6764273.9 | L16: 675252.22 | M16: =+L16/K16 -> 0.099826268
A17: May | B17: 380 | C17: 423404 | D17: 7404120.2 | E17: 926330.26 | F17: =+E17/D17 -> 0.12511011 | H17: May | I17: 375 | J17: 411285 | K17: 6730544.5 | L17: 728106.35 | M17: =+L17/K17 -> 0.10817941
A18: June | B18: 395 | C18: 437568 | D18: 8105846 | E18: 1036575.5 | F18: =+E18/D18 -> 0.12787999 | H18: June | I18: 390 | J18: 426174 | K18: 7478817.1 | L18: 804289.66 | M18: =+L18/K18 -> 0.10754236
A19: July | B19: 451 | C19: 378098 | D19: 8643126 | E19: 987455.09 | F19: 0.11424745 | H19: July | I19: 443 | J19: 367439 | K19: 8070249 | L19: x | M19: 0.096273514
A22: Product Wise Bifurcation
B23: Select the Product Type → | E23: Old Line
A25: Purchase Analysis | H25: Purchase Analysis - Removed Top 5
A26: Month | B26: Unique products | C26: Boxes | D26: Purchase Value | E26: Potential Profit | F26: Margin | H26: Month | I26: Unique products | J26: Boxes | K26: Purchase Value | L26: Potential Profit | M26: Margin
A27: Feb | B27: =COUNTIFS(Raw!D:D,'Updated Summary'!E23,Raw!J:J,">0") -> 279 | C27: =SUMIFS(Raw!J:J,Raw!$D:$D,'Updated Summary'!$E$23) -> 367568.06 | D27: =SUMIFS(Raw!AO:AO,Raw!$D:$D,'Updated Summary'!$E$23) -> 7055393 | E27: =SUMIFS(Raw!P:P,Raw!$D:$D,'Updated Summary'!$E$23) -> 1616962.7 | F27: =+E27/D27 -> 0.22918109 | H27: Feb | I27: =COUNTIFS(Raw!D:D,'Updated Summary'!E23,Raw!J:J,">0",Raw!C:C,"<>Top 5") -> 273 | J27: =SUMIFS(Raw!J:J,Raw!$D:$D,'Updated Summary'!$E$23,Raw!C:C,"<>Top 5") -> 345672.36 | K27: =SUMIFS(Raw!AO:AO,Raw!$D:$D,'Updated Summary'!$E$23,Raw!C:C,"<>Top 5") -> 6468748.1 | L27: =SUMIFS(Raw!P:P,Raw!$D:$D,'Updated Summary'!$E$23,Raw!C:C,"<>Top 5") -> 784284.86 | M27: =+L27/K27 -> 0.12124214
A28: Mar | B28: =COUNTIFS(Raw!D:D,'Updated Summary'!E23,Raw!K:K,">0") -> 243 | C28: =SUMIFS(Raw!K:K,Raw!$D:$D,'Updated Summary'!$E$23) -> 294215.25 | D28: =SUMIFS(Raw!AP:AP,Raw!$D:$D,'Updated Summary'!$E$23) -> 5546326.8 | E28: =SUMIFS(Raw!Q:Q,Raw!$D:$D,'Updated Summary'!$E$23) -> 981990.41 | F28: =+E28/D28 -> 0.17705239 | H28: Mar | I28: =COUNTIFS(Raw!D:D,'Updated Summary'!E23,Raw!K:K,">0",Raw!C:C,"<> Top 5",Raw!C:C,"<>Top 5") -> 238 | J28: =SUMIFS(Raw!K:K,Raw!$D:$D,'Updated Summary'!$E$23,Raw!C:C,"<>Top 5") -> 281476.91 | K28: =SUMIFS(Raw!AP:AP,Raw!$D:$D,'Updated Summary'!$E$23,Raw!C:C,"<>Top 5") -> 5166717 | L28: =SUMIFS(Raw!Q:Q,Raw!$D:$D,'Updated Summary'!$E$23,Raw!C:C,"<>Top 5") -> 614441.36 | M28: =+L28/K28 -> 0.11892298
A29: April | B29: =COUNTIFS(Raw!D:D,'Updated Summary'!E23,Raw!L:L,">0") -> 230 | C29: =SUMIFS(Raw!L:L,Raw!$D:$D,'Updated Summary'!$E$23) -> 254854.52 | D29: =SUMIFS(Raw!AQ:AQ,Raw!$D:$D,'Updated Summary'!$E$23) -> 6181422.4 | E29: =SUMIFS(Raw!R:R,Raw!$D:$D,'Updated Summary'!$E$23) -> 1037936.2 | F29: =+E29/D29 -> 0.1679122 | H29: April | I29: =COUNTIFS(Raw!D:D,'Updated Summary'!E23,Raw!L:L,">0",Raw!C:C,"<>Top 5") -> 225 | J29: =SUMIFS(Raw!L:L,Raw!$D:$D,'Updated Summary'!$E$23,Raw!C:C,"<>Top 5") -> 243274.72 | K29: =SUMIFS(Raw!AQ:AQ,Raw!$D:$D,'Updated Summary'!$E$23,Raw!C:C,"<>Top 5") -> 5852920 | L29: =SUMIFS(Raw!R:R,Raw!$D:$D,'Updated Summary'!$E$23,Raw!C:C,"<>Top 5") -> 654815.95 | M29: =+L29/K29 -> 0.11187851
A30: May | B30: =COUNTIFS(Raw!D:D,'Updated Summary'!E23,Raw!M:M,">0") -> 238 | C30: =SUMIFS(Raw!M:M,Raw!$D:$D,'Updated Summary'!$E$23) -> 325821.86 | D30: =SUMIFS(Raw!AR:AR,Raw!$D:$D,'Updated Summary'!$E$23) -> 6323811.2 | E30: =SUMIFS(Raw!S:S,Raw!$D:$D,'Updated Summary'!$E$23) -> 1162311.8 | F30: =+E30/D30 -> 0.18379925 | H30: May | I30: =COUNTIFS(Raw!D:D,'Updated Summary'!E23,Raw!M:M,">0",Raw!C:C,"<>Top 5") -> 232 | J30: =SUMIFS(Raw!M:M,Raw!$D:$D,'Updated Summary'!$E$23,Raw!C:C,"<>Top 5") -> 314379.44 | K30: =SUMIFS(Raw!AR:AR,Raw!$D:$D,'Updated Summary'!$E$23,Raw!C:C,"<>Top 5") -> 6100277.3 | L30: =SUMIFS(Raw!S:S,Raw!$D:$D,'Updated Summary'!$E$23,Raw!C:C,"<>Top 5") -> 740707.8 | M30: =+L30/K30 -> 0.12142199
A31: June | B31: =COUNTIFS(Raw!D:D,'Updated Summary'!E23,Raw!N:N,">0") -> 253 | C31: =SUMIFS(Raw!N:N,Raw!$D:$D,'Updated Summary'!$E$23) -> 293587.58 | D31: =SUMIFS(Raw!AS:AS,Raw!$D:$D,'Updated Summary'!$E$23) -> 5744574.2 | E31: =SUMIFS(Raw!T:T,Raw!$D:$D,'Updated Summary'!$E$23) -> 1019523.3 | F31: =+E31/D31 -> 0.17747587 | H31: June | I31: =COUNTIFS(Raw!D:D,'Updated Summary'!E23,Raw!N:N,">0",Raw!C:C,"<>Top 5") -> 246 | J31: =SUMIFS(Raw!N:N,Raw!$D:$D,'Updated Summary'!$E$23,Raw!C:C,"<>Top 5") -> 281227.67 | K31: =SUMIFS(Raw!AS:AS,Raw!$D:$D,'Updated Summary'!$E$23,Raw!C:C,"<>Top 5") -> 5521600.1 | L31: =SUMIFS(Raw!T:T,Raw!$D:$D,'Updated Summary'!$E$23,Raw!C:C,"<>Top 5") -> 629816.79 | M31: =+L31/K31 -> 0.11406418
A32: July | B32: =COUNTIFS(Raw!D:D,'Updated Summary'!E23,Raw!O:O,">0") -> 280 | C32: =SUMIFS(Raw!O:O,Raw!$D:$D,'Updated Summary'!$E$23) -> 402727 | D32: =SUMIFS(Raw!AT:AT,Raw!$D:$D,'Updated Summary'!$E$23) -> 6958472 | E32: =SUMIFS(Raw!U:U,Raw!$D:$D,'Updated Summary'!$E$23) -> 1646964.9 | F32: =+E32/D32 -> 0.23668485 | H32: July | I32: =COUNTIFS(Raw!D:D,'Updated Summary'!E23,Raw!O:O,">0",Raw!C:C,"<>Top 5") -> 273 | J32: =SUMIFS(Raw!O:O,Raw!$D:$D,'Updated Summary'!$E$23,Raw!C:C,"<>Top 5") -> 377665 | K32: =SUMIFS(Raw!AT:AT,Raw!$D:$D,'Updated Summary'!$E$23,Raw!C:C,"<>Top 5") -> 6177057.7 | L32: =SUMIFS(Raw!U:U,Raw!$D:$D,'Updated Summary'!$E$23,Raw!C:C,"<>Top 5") -> 844908.83 | M32: =+L32/K32 -> 0.13678176
A34: Sales Analysis | H34: Sales Analysis - Removed Top 5 Profit
A35: Month | B35: Unique products | C35: Boxes | D35: Sales Value | E35: Profit | F35: Margin | H35: Month | I35: Unique products | J35: Boxes | K35: Sales Value | L35: Profit | M35: Margin
A36: Feb | B36: =COUNTIFS(Raw!D:D,'Updated Summary'!E23,Raw!V:V,">0") -> 351 | C36: =SUMIFS(Raw!V:V,Raw!$D:$D,'Updated Summary'!$E$23) -> 310056 | D36: =SUMIFS(Raw!AU:AU,Raw!$D:$D,'Updated Summary'!$E$23) -> 5572274 | E36: =SUMIFS(Raw!AH:AH,Raw!$D:$D,'Updated Summary'!$E$23) -> 652436.03 | F36: =+E36/D36 -> 0.11708614 | H36: Feb | I36: =COUNTIFS(Raw!D:D,'Updated Summary'!E23,Raw!V:V,">0",Raw!C:C,"<>Top 5") -> 344 | J36: =SUMIFS(Raw!V:V,Raw!$D:$D,'Updated Summary'!$E$23,Raw!C:C,"<>Top 5") -> 296790 | K36: =SUMIFS(Raw!AU:AU,Raw!$D:$D,'Updated Summary'!$E$23,Raw!C:C,"<>Top 5") -> 5147573.8 | L36: =SUMIFS(Raw!AH:AH,Raw!$D:$D,'Updated Summary'!$E$23,Raw!C:C,"<>Top 5") -> 441523.76 | M36: =+L36/K36 -> 0.085773178
A37: Mar | B37: =COUNTIFS(Raw!D:D,'Updated Summary'!E23,Raw!W:W,">0") -> 355 | C37: =SUMIFS(Raw!W:W,Raw!$D:$D,'Updated Summary'!$E$23) -> 352108 | D37: =SUMIFS(Raw!AV:AV,Raw!$D:$D,'Updated Summary'!$E$23) -> 6921976.4 | E37: =SUMIFS(Raw!AI:AI,Raw!$D:$D,'Updated Summary'!$E$23) -> 785247.73 | F37: =+E37/D37 -> 0.11344271 | H37: Mar | I37: =COUNTIFS(Raw!D:D,'Updated Summary'!E23,Raw!W:W,">0",Raw!C:C,"<>Top 5") -> 348 | J37: =SUMIFS(Raw!W:W,Raw!$D:$D,'Updated Summary'!$E$23,Raw!C:C,"<>Top 5") -> 336422 | K37: =SUMIFS(Raw!AV:AV,Raw!$D:$D,'Updated Summary'!$E$23,Raw!C:C,"<>Top 5") -> 6308516.7 | L37: =SUMIFS(Raw!AI:AI,Raw!$D:$D,'Updated Summary'!$E$23,Raw!C:C,"<>Top 5") -> 571678.21 | M37: =+L37/K37 -> 0.090620067
A38: April | B38: =COUNTIFS(Raw!D:D,'Updated Summary'!E23,Raw!X:X,">0") -> 358 | C38: =SUMIFS(Raw!X:X,Raw!$D:$D,'Updated Summary'!$E$23) -> 394929 | D38: =SUMIFS(Raw!AW:AW,Raw!$D:$D,'Updated Summary'!$E$23) -> 5977043.2 | E38: =SUMIFS(Raw!AJ:AJ,Raw!$D:$D,'Updated Summary'!$E$23) -> 819127.8 | F38: =+E38/D38 -> 0.13704566 | H38: April | I38: =COUNTIFS(Raw!D:D,'Updated Summary'!E23,Raw!X:X,">0",Raw!C:C,"<>Top 5") -> 352 | J38: =SUMIFS(Raw!X:X,Raw!$D:$D,'Updated Summary'!$E$23,Raw!C:C,"<>Top 5") -> 383357 | K38: =SUMIFS(Raw!AW:AW,Raw!$D:$D,'Updated Summary'!$E$23,Raw!C:C,"<>Top 5") -> 5539529.8 | L38: =SUMIFS(Raw!AJ:AJ,Raw!$D:$D,'Updated Summary'!$E$23,Raw!C:C,"<>Top 5") -> 600248.28 | M38: =+L38/K38 -> 0.10835726
A39: May | B39: =COUNTIFS(Raw!D:D,'Updated Summary'!E23,Raw!Y:Y,">0") -> 349 | C39: =SUMIFS(Raw!Y:Y,Raw!$D:$D,'Updated Summary'!$E$23) -> 370672 | D39: =SUMIFS(Raw!AX:AX,Raw!$D:$D,'Updated Summary'!$E$23) -> 5858100.9 | E39: =SUMIFS(Raw!AK:AK,Raw!$D:$D,'Updated Summary'!$E$23) -> 880351.77 | F39: =+E39/D39 -> 0.15027938 | H39: May | I39: =COUNTIFS(Raw!D:D,'Updated Summary'!E23,Raw!Y:Y,">0",Raw!C:C,"<>Top 5") -> 342 | J39: =SUMIFS(Raw!Y:Y,Raw!$D:$D,'Updated Summary'!$E$23,Raw!C:C,"<>Top 5") -> 355466 | K39: =SUMIFS(Raw!AX:AX,Raw!$D:$D,'Updated Summary'!$E$23,Raw!C:C,"<>Top 5") -> 5327873 | L39: =SUMIFS(Raw!AK:AK,Raw!$D:$D,'Updated Summary'!$E$23,Raw!C:C,"<>Top 5") -> 627949.8 | M39: =+L39/K39 -> 0.11786126
A40: June | B40: =COUNTIFS(Raw!D:D,'Updated Summary'!E23,Raw!Z:Z,">0") -> 356 | C40: =SUMIFS(Raw!Z:Z,Raw!$D:$D,'Updated Summary'!$E$23) -> 384155 | D40: =SUMIFS(Raw!AY:AY,Raw!$D:$D,'Updated Summary'!$E$23) -> 6509978.8 | E40: =SUMIFS(Raw!AL:AL,Raw!$D:$D,'Updated Summary'!$E$23) -> 965355.35 | F40: =+E40/D40 -> 0.14828856 | H40: June | I40: =COUNTIFS(Raw!D:D,'Updated Summary'!E23,Raw!Z:Z,">0",Raw!C:C,"<>Top 5") -> 349 | J40: =SUMIFS(Raw!Z:Z,Raw!$D:$D,'Updated Summary'!$E$23,Raw!C:C,"<>Top 5") -> 370620 | K40: =SUMIFS(Raw!AY:AY,Raw!$D:$D,'Updated Summary'!$E$23,Raw!C:C,"<>Top 5") -> 6067897.6 | L40: =SUMIFS(Raw!AL:AL,Raw!$D:$D,'Updated Summary'!$E$23,Raw!C:C,"<>Top 5") -> 671507.83 | M40: =+L40/K40 -> 0.11066565
A41: July | B41: =COUNTIFS(Raw!D:D,'Updated Summary'!E23,Raw!AA:AA,">0") -> 361 | C41: =SUMIFS(Raw!AA:AA,Raw!$D:$D,'Updated Summary'!$E$23) -> 420696 | D41: =SUMIFS(Raw!AZ:AZ,Raw!$D:$D,'Updated Summary'!$E$23) -> 6910328.7 | E41: =SUMIFS(Raw!AM:AM,Raw!$D:$D,'Updated Summary'!$E$23) -> 840687.5 | F41: =+E41/D41 -> 0.12165666 | H41: July | I41: =COUNTIFS(Raw!D:D,'Updated Summary'!E23,Raw!AA:AA,">0",Raw!C:C,"<>Top 5") -> 354 | J41: =SUMIFS(Raw!AA:AA,Raw!$D:$D,'Updated Summary'!$E$23,Raw!C:C,"<>Top 5") -> 410543 | K41: =SUMIFS(Raw!AZ:AZ,Raw!$D:$D,'Updated Summary'!$E$23,Raw!C:C,"<>Top 5") -> 6594066.7 | L41: =SUMIFS(Raw!AM:AM,Raw!$D:$D,'Updated Summary'!$E$23,Raw!C:C,"<>Top 5") -> 628428.5 | M41: =+L41/K41 -> 0.095302114

Sheet Raw
A1: Lax Part No | B1: Lax Description | C1: Top/Bottom | D1: Type | E1: Profit Per Pack | F1: Qty Target | G1: Monthly | H1: PCA | I1: Monthly Requirement Against PCA | J1: Feb'26 Received Qty | K1: March'26 Received Qty | L1: Apr'26 Received Qty | M1: May'26 Received Qty | N1: June'26 Received Qty | O1: July'26 Received Qty | P1: Feb'26 Potential Profit | Q1: March'26 Potential Profit | R1: Apr'26 Potential Profit | S1: May'26 Potential Profit | T1: June'26 Potential Profit | U1: July'26 Potential Profit | V1: Feb'26 Selling Qty | W1: March'26 Selling Qty | X1: Apr'26 Selling Qty | Y1: May'26 Selling Qty | Z1: June'26 Selling Qty | AA1: July'26 Selling Qty | AB1: Feb'26 Selling Qty | AC1: March'26 Selling Qty | AD1: Apr'26 Selling Qty | AE1: May'26 Selling Qty | AF1: June'26 Selling Qty | AG1: July'26 Selling Qty | AH1: Feb'26 Profit | AI1: March'26 Profit | AJ1: Apr'26 Profit | AK1: May'26 Profit | AL1: June'26 Profit | AM1: July'26 Profit | AN1: Category | AO1: Feb'26 Purchase Value | AP1: March'26 Purchase Value | AQ1: Apr'26 Purchase Value | AR1: May'26 Purchase Value | AS1: June'26 Purchase Value | AT1: July'26 Purchase Value | AU1: Feb'26 Sales Value | AV1: March'26 Sales Value | AW1: Apr'26 Sales Value | AX1: May'26 Sales Value | AY1: June'26 Sales Value | AZ1: July'26 Sales Value
A2: 1459 | B2: Trihexyphenidyl 2mg Tablets 100 | C2: Top 5 | D2: Old Line | E2: 95.44 | F2: 3000 | G2: =F2/2 -> 1500 | H2: 6291 | I2: =+G2/H2 -> 0.23843586 | J2: 7002.5 | K2: 2504 | L2: 2842 | M2: 2186.75 | N2: 904.25 | O2: 3198 | P2: =+J2*E2 -> 668318.6 | Q2: =+K2*E2 -> 238981.76 | R2: =+L2*E2 -> 271240.48 | S2: =+M2*E2 -> 208703.42 | T2: =+N2*E2 -> 86301.62 | U2: =+O2*E2 -> 305217.12 | V2: =726+435 -> 1161 | W2: =991+504 -> 1495 | X2: =778+776 -> 1554 | Y2: =867+693 -> 1560 | Z2: =890+884 -> 1774 | AA2: 805 | AB2: =+IFERROR(V2/H2,"") -> 0.18454936 | AC2: =+IFERROR(W2/H2,"") -> 0.23764107 | AD2: =+IFERROR(X2/H2,"") -> 0.24701955 | AE2: =+IFERROR(Y2/H2,"") -> 0.2479733 | AF2: =+IFERROR(Z2/H2,"") -> 0.28199014 | AG2: =+IFERROR(AA2/H2,"") -> 0.12796058 | AH2: 104490 | AI2: 134550 | AJ2: 139860 | AK2: 140400 | AL2: 159660 | AM2: 70979.12 | AN2: Above 11% | AO2: 25052.72 | AP2: 11618.56 | AQ2: 13205.2 | AR2: 10137.65 | AS2: 4159.55 | AT2: 3668.1 | AU2: 0 | AV2: 0 | AW2: 0 | AX2: 0 | AY2: 0 | AZ2: 0 | BB2: Old Line
A3: L1515 | B3: Ontozry 150mg Tabs 28 | D3: New Line | E3: 90.75627 | F3: 1500 | G3: =F3/2 -> 750 | H3: 1212 | I3: =+G3/H3 -> 0.61881188 | J3: 0 | K3: 0 | L3: 0 | M3: 0 | N3: 0 | O3: 55 | U3: =+O3*E3 -> 4991.5949 | AB3: =+IFERROR(V3/H3,"") -> 0 | AC3: =+IFERROR(W3/H3,"") -> 0 | AD3: =+IFERROR(X3/H3,"") -> 0 | AE3: =+IFERROR(Y3/H3,"") -> 0 | AF3: =+IFERROR(Z3/H3,"") -> 0 | AG3: =+IFERROR(AA3/H3,"") -> 0 | AN3: Above 11% | AO3: 0 | AP3: 0 | AQ3: 0 | AR3: 0 | AS3: 0 | AT3: 4867.5 | AU3: 0 | AV3: 0 | AW3: 0 | AX3: 17383.69 | AY3: 13701.49 | AZ3: 0 | BB3: New Line
A4: 4092A | B4: Olsalazine 500mg Tablets 60 | D4: Old Line | E4: 89.98 | F4: 150 | G4: =F4/2 -> 75 | H4: 305 | I4: =+G4/H4 -> 0.24590164 | J4: 0 | K4: 0 | L4: 0 | M4: 50 | N4: 40 | O4: 0 | P4: =+J4*E4 -> 0 | Q4: =+K4*E4 -> 0 | R4: =+L4*E4 -> 0 | S4: =+M4*E4 -> 4499 | T4: =+N4*E4 -> 3599.2 | U4: =+O4*E4 -> 0 | V4: 2 | W4: 0 | X4: 0 | Y4: 0 | Z4: 49 | AA4: 39 | AB4: =+IFERROR(V4/H4,"") -> 0.006557377 | AC4: =+IFERROR(W4/H4,"") -> 0 | AD4: =+IFERROR(X4/H4,"") -> 0 | AE4: =+IFERROR(Y4/H4,"") -> 0 | AF4: =+IFERROR(Z4/H4,"") -> 0.16065574 | AG4: =+IFERROR(AA4/H4,"") -> 0.12786885 | AH4: 184.86 | AI4: 0 | AJ4: 0 | AK4: 0 | AL4: 4409.02 | AM4: 3461.86 | AN4: Above 11% | AO4: 0 | AP4: 0 | AQ4: 0 | AR4: 2809.5 | AS4: 2220.4 | AT4: 0 | AU4: 293.98 | AV4: 0 | AW4: 0 | AX4: 0 | AY4: 6872.95 | AZ4: 5626.75
A5: 5678 | B5: Olsalazine 500mg Tablets 100 | D5: Old Line | E5: 83.25 | F5: 300 | G5: =F5/2 -> 150 | H5: 305 | I5: =+G5/H5 -> 0.49180328 | J5: 273 | K5: 0 | L5: 0 | M5: 0 | O5: 0 | P5: =+J5*E5 -> 22727.25 | Q5: =+K5*E5 -> 0 | R5: =+L5*E5 -> 0 | S5: =+M5*E5 -> 0 | T5: =+N5*E5 -> 0 | U5: =+O5*E5 -> 0 | V5: 19 | W5: 36 | X5: 90 | Y5: 97 | Z5: 74 | AA5: 0 | AB5: =+IFERROR(V5/H5,"") -> 0.062295082 | AC5: =+IFERROR(W5/H5,"") -> 0.11803279 | AD5: =+IFERROR(X5/H5,"") -> 0.29508197 | AE5: =+IFERROR(Y5/H5,"") -> 0.31803279 | AF5: =+IFERROR(Z5/H5,"") -> 0.24262295 | AG5: =+IFERROR(AA5/H5,"") -> 0 | AH5: 1711.2 | AI5: 4335.88 | AJ5: 4335.88 | AK5: 8516.17 | AL5: 7774.44 | AM5: 0 | AN5: Above 11% | AO5: 15313 | AP5: 0 | AQ5: 0 | AR5: 0 | AS5: 0 | AT5: 0 | AU5: 0 | AV5: 0 | AW5: 0 | AX5: 0 | AY5: 0 | AZ5: 0
A6: 5678A | B6: Dipentum 250mg Capsules 100 | D6: Old Line | E6: 77.07 | F6: 200 | G6: =F6/2 -> 100 | H6: 305 | I6: =+G6/H6 -> 0.32786885 | J6: 353 | K6: 130 | L6: 0 | M6: 0 | O6: 0 | P6: =+J6*E6 -> 27205.71 | Q6: =+K6*E6 -> 10019.1 | R6: =+L6*E6 -> 0 | S6: =+M6*E6 -> 0 | T6: =+N6*E6 -> 0 | U6: =+O6*E6 -> 0 | V6: 0 | W6: 0 | X6: 0 | Y6: 20 | Z6: 24 | AA6: 44 | AB6: =+IFERROR(V6/H6,"") -> 0 | AC6: =+IFERROR(W6/H6,"") -> 0 | AD6: =+IFERROR(X6/H6,"") -> 0 | AE6: =+IFERROR(Y6/H6,"") -> 0.06557377 | AF6: =+IFERROR(Z6/H6,"") -> 0.078688525 | AG6: =+IFERROR(AA6/H6,"") -> 0.1442623 | AH6: 0 | AI6: 0 | AJ6: 0 | AK6: 1541.4 | AL6: 1631.4 | AM6: 3449.16 | AN6: Above 11% | AO6: 12284.81 | AP6: 4529.2 | AQ6: 0 | AR6: 0 | AS6: 0 | AT6: 0 | AU6: 0 | AV6: 0 | AW6: 0 | AX6: 2320 | AY6: 2743.5 | AZ6: 4964.08
A7: 5440 | B7: Norprolac 75mcg Tablets 30s | D7: Old Line | E7: 51.94 | F7: 400 | G7: =F7/2 -> 200 | H7: 269 | I7: =+G7/H7 -> 0.74349442 | J7: 98 | K7: 0 | L7: 0 | M7: 0 | O7: 30 | P7: =+J7*E7 -> 5090.12 | Q7: =+K7*E7 -> 0 | R7: =+L7*E7 -> 0 | S7: =+M7*E7 -> 0 | T7: =+N7*E7 -> 0 | U7: =+O7*E7 -> 1558.2 | V7: 0 | W7: 0 | X7: 0 | Y7: 1 | Z7: 0 | AA7: 0 | AB7: =+IFERROR(V7/H7,"") -> 0 | AC7: =+IFERROR(W7/H7,"") -> 0 | AD7: =+IFERROR(X7/H7,"") -> 0 | AE7: =+IFERROR(Y7/H7,"") -> 0.0037174721 | AF7: =+IFERROR(Z7/H7,"") -> 0 | AG7: =+IFERROR(AA7/H7,"") -> 0 | AH7: 0 | AI7: 0 | AJ7: 0 | AK7: 51.94 | AL7: 51.94 | AM7: 0 | AN7: Above 11% | AO7: 2316.56 | AP7: 0 | AQ7: 0 | AR7: 0 | AS7: 0 | AT7: 702.6 | AU7: 0 | AV7: 0 | AW7: 0 | AX7: 0 | AY7: 0 | AZ7: 0
